{"ID": "350fd9ad-0f07-4b79-9705-a6c1b6bd2cfb", "effective_cve": "CVE-2021-3426", "image": {"exact": "gcr.io/distroless/python3-debian11@sha256:69ae7f133d33faab720af28e78fb45707b623bcbc94ae02a07c633bf053f4b40"}, "label": "TP", "package": {"name": "libpython3.9-stdlib", "version": "3.9.2-1"}, "timestamp": "2023-06-30T12:37:01.550168", "tool": "grype@v0.63.0", "user": "westonsteimel", "vulnerability_id": "CVE-2021-3426"}