{"ID": "14ef8018-d9ff-47a5-bdbf-af17d4cd385a", "effective_cve": "CVE-2020-26116", "image": {"exact": "docker.io/cloudbees/cloudbees-core-mm@sha256:4c564f473d38f23da1caa48c4ef53b958ef03d279232007ad3319b1f38584bdb"}, "label": "TP", "package": {"name": "platform-python", "version": "3.6.8-31.el8"}, "timestamp": "2022-09-06T21:59:51-04:00", "user": "samdacanay", "vulnerability_id": "CVE-2020-26116"}