{"ID": "1e04889b-28ac-491f-8756-7bc1f65e8265", "effective_cve": "CVE-2020-26116", "image": {"exact": "docker.io/python@sha256:5e96e03a493a54904aa8be573fc0414431afb4f47ac58fbffd03b2a725005364"}, "label": "TP", "package": {"name": "python", "version": "3.8.0"}, "timestamp": "2022-09-30T13:40:40+01:00", "user": "westonsteimel", "vulnerability_id": "CVE-2020-26116"}